Workbook

Sheet Summary
A1: Standeliver
A2: US Stadiums & Arenas
B4: Description | D4: Stadiums - All | E4: Arenas - Private | F4: College Arenas | G4: College Arenas | I4: Total US
B5: Capacity | F5: > 10k | G5: 5k - 10k | I5: Market
B7: FACILITIES DATA
B8: Total Facilities | D8: =Stadiums!B416 -> 406 | E8: =Arenas!B542 -> 531 | F8: ='College Arenas > 10,000'!B101 -> 92 | G8: ='College Arenas 5,000-10,000'!B179 -> 171 | I8: =SUM(D8:G8) -> 1200
B9: Total Facility Capacity | D9: =Stadiums!D418 -> 13396158 | E9: =Arenas!J544 -> 4089018.3 | F9: ='College Arenas > 10,000'!I103 -> 1226573.8 | G9: ='College Arenas 5,000-10,000'!I181 -> 1143341 | I9: =SUM(D9:G9) -> 19855091
B12: LOW ATTENDANCE
B13: Low Attendance | D13: 0.3 | E13: 0.3 | F13: 0.3 | G13: 0.3 | I13: 0.3
B14: Average Participation | D14: =(0.05+0.3)/2 -> 0.175 | E14: =(0.05+0.3)/2 -> 0.175 | F14: =(0.05+0.3)/2 -> 0.175 | G14: =(0.05+0.3)/2 -> 0.175 | I14: =(0.05+0.3)/2 -> 0.175
B15: Total Transactions per Event | D15: =D9*D13*D14 -> 703298.3 | E15: =E9*E13*E14 -> 214673.46 | F15: =F9*F13*F14 -> 64395.126 | G15: =G9*G13*G14 -> 60025.402 | I15: =I9*I13*I14 -> 1042392.3
B16: Transaction Fee | D16: 4 | E16: 4 | F16: 4 | G16: 4 | I16: 4
B17: Potential Monthly Revenue | D17: =D15*D16 -> 2813193.2 | E17: =E15*E16 -> 858693.85 | F17: =F15*F16 -> 257580.51 | G17: =G15*G16 -> 240101.61 | I17: =I15*I16 -> 4169569.1
B18: Potential Annual Revenue | D18: =D17*12 -> 33758318 | E18: =E17*12 -> 10304326 | F18: =F17*12 -> 3090966.1 | G18: =G17*12 -> 2881219.3 | I18: =I17*12 -> 50034830
B21: AVERAGE ATTENDANCE
B22: Average Attendance | D22: =(0.5+0.75)/2 -> 0.625 | E22: =(0.5+0.75)/2 -> 0.625 | F22: =(0.5+0.75)/2 -> 0.625 | G22: =(0.5+0.75)/2 -> 0.625 | I22: =(0.5+0.75)/2 -> 0.625
B23: Average Participation | D23: =(0.05+0.3)/2 -> 0.175 | E23: =(0.05+0.3)/2 -> 0.175 | F23: =(0.05+0.3)/2 -> 0.175 | G23: =(0.05+0.3)/2 -> 0.175 | I23: =(0.05+0.3)/2 -> 0.175
B24: Total Transactions per Event | D24: =D9*D22*D23 -> 1465204.8 | E24: =E9*E22*E23 -> 447236.38 | F24: =F9*F22*F23 -> 134156.51 | G24: =G9*G22*G23 -> 125052.92 | I24: =I9*I22*I23 -> 2171650.6
B25: Transaction Fee | D25: 4 | E25: 4 | F25: 4 | G25: 4 | I25: 4
B26: Potential Monthly Revenue | D26: =D24*D25 -> 5860819.1 | E26: =E24*E25 -> 1788945.5 | F26: =F24*F25 -> 536626.05 | G26: =G24*G25 -> 500211.69 | I26: =I24*I25 -> 8686602.4
B27: Potential Annual Revenue | D27: =D26*12 -> 70329830 | E27: =E26*12 -> 21467346 | F27: =F26*12 -> 6439512.6 | G27: =G26*12 -> 6002540.2 | I27: =I26*12 -> 1.0423923e+08
D29: Assuming one event per month, 12 per year per facility.
D31: NFL Home games = approx 8 or 9 = .75 events per month average
D32: Major League Baseball = 81 games = 6.75 events per month average
D33: NHL Home Games = 41 = 3.42 events per month average
D34: NBA Home Games = 41 = 3.42 eventa per month average
D36: Does not include preseason or playoff games in NFL/MLB/NHL/NBA totals
D37: Does not include High School/Middle School stadiums
D38: Does not include College or High School baseball stadiums
D39: Source of Stadium/Arena data: Wikipedia

Sheet Stadiums
A1: Stadiums in the United States
A2: Capacity > 10,000
B4: The following is a list of stadiums in the United States. They are ranked by capacity, which is the maximum number of spectators the stadium can normally accommodate. All U.S. stadiums with a current
B5: capacity of 10,000 or more are included in the list. The majority of these stadiums are used for American football, either in college football or the NFL. Most of the others are Major League Baseball
B6: ballparks or Major League Soccer stadiums.
B7: https://en.wikipedia.org/wiki/List_of_U.S._stadiums_by_capacity
B9: Rows shaded in yellow indicates stadium is home to an NFL, MLB, MLS, or NWSL franchise.
B10: Rank | C10: Stadium | D10: Capacity | E10: City | F10: State | G10: Year opened | H10: Type | I10: Tenant
B11: 1 | C11: Michigan Stadium[1] | D11: 107601 | E11: Ann Arbor | F11: Michigan | G11: 1927 | H11: Football | I11: Michigan Wolverines (NCAA)
B12: 2 | C12: Beaver Stadium[2] | D12: 106572 | E12: University Park | F12: Pennsylvania | G12: 1960 | H12: Football | I12: Penn State Nittany Lions (NCAA)
B13: 3 | C13: Ohio Stadium[3] | D13: 102780 | E13: Columbus | F13: Ohio | G13: 1922 | H13: Football | I13: Ohio State Buckeyes (NCAA)
B14: 4 | C14: Kyle Field | D14: 102733 | E14: College Station | F14: Texas | G14: 1927 | H14: Football | I14: Texas A&M Aggies (NCAA)
B15: 5 | C15: Tiger Stadium[4] | D15: 102321 | E15: Baton Rouge | F15: Louisiana | G15: 1924 | H15: Football | I15: LSU Tigers (NCAA)
B16: 6 | C16: Neyland Stadium[5] | D16: 101915 | E16: Knoxville | F16: Tennessee | G16: 1921 | H16: Football | I16: Tennessee Volunteers (NCAA)
B17: 7 | C17: Darrell K Royal–Texas Memorial Stadium[6] | D17: 100119 | E17: Austin | F17: Texas | G17: 1924 | H17: Football | I17: Texas Longhorns (NCAA)
B18: 8 | C18: Bryant–Denny Stadium[7] | D18: 100077 | E18: Tuscaloosa | F18: Alabama | G18: 1929 | H18: Football | I18: Alabama Crimson Tide (NCAA)
B19: 9 | C19: Sanford Stadium[8] | D19: 92746 | E19: Athens | F19: Georgia | G19: 1929 | H19: Football | I19: Georgia Bulldogs (NCAA)
B20: 10 | C20: Rose Bowl[9] | D20: 92542 | E20: Pasadena | F20: California | G20: 1922 | H20: Football | I20: UCLA Bruins (NCAA) Rose Bowl Game (NCAA)
B21: 11 | C21: Cotton Bowl | D21: 92100 | E21: Dallas | F21: Texas | G21: 1930 | H21: Football | I21: Red River Rivalry (NCAA) State Fair Classic (NCAA)
B22: 12 | C22: Ben Hill Griffin Stadium[10] | D22: 88548 | E22: Gainesville | F22: Florida | G22: 1930 | H22: Football | I22: Florida Gators (NCAA)
... B42: 32 | C42: Highmark Stadium | D42: 71608 | E42: Orchard Park | F42: New York | G42: 1973 | H42: Football | I42: Buffalo Bills (NFL)
B43: 33 | C43: Legion Field | D43: 71594 | E43: Birmingham | F43: Alabama | G43: 1926 | H43: Football
B44: 34 | C44: Mercedes-Benz Stadium | D44: 71000 | E44: Atlanta | F44: Georgia | G44: 2017 | H44: Football, soccer | I44: Atlanta Falcons (NFL) Atlanta United FC (MLS) Peach Bowl (NCAA) SEC Championship Game (NCAA)
B45: 35 | C45: M&T Bank Stadium | D45: 70745 | E45: Baltimore | F45: Maryland | G45: 1998 | H45: Football | I45: Baltimore Ravens (NFL)
B46: 36 | C46: SoFi Stadium | D46: 70240 | E46: Inglewood | F46: California | G46: 2020 | H46: Football | I46: Los Angeles Rams (NFL) Los Angeles Chargers (NFL) LA Bowl (NCAA)
B47: 37 | C47: Husky Stadium | D47: 70083 | E47: Seattle | F47: Washington | G47: 1920 | H47: Football | I47: Washington Huskies (NCAA)
B48: 38 | C48: Kinnick Stadium | D48: 69250 | E48: Iowa City | F48: Iowa | G48: 1929 | H48: Football | I48: Iowa Hawkeyes (NCAA)
B49: 39 | C49: Raymond James Stadium | D49: 69218 | E49: Tampa | F49: Florida | G49: 1998 | H49: Football | I49: Tampa Bay Buccaneers (NFL) South Florida Bulls (NCAA) Tampa Bay Bowl (NCAA) Gasparilla Bowl (NCAA)
B50: 40 | C50: Nissan Stadium | D50: 69143 | E50: Nashville | F50: Tennessee | G50: 1999 | H50: Football | I50: Tennessee Titans (NFL) Tennessee State Tigers (NCAA) Music City Bowl (NCAA)
B51: 41 | C51: Lumen Field | D51: 68740 | E51: Seattle | F51: Washington | G51: 2002 | H51: Football, soccer | I51: Seattle Seahawks (NFL) Seattle Sounders FC (MLS) Seattle Reign FC (NWSL)
B52: 42 | C52: Levi's Stadium | D52: 68500 | E52: Santa Clara | F52: California | G52: 2014 | H52: Football | I52: San Francisco 49ers (NFL)
B53: 43 | C53: Acrisure Stadium | D53: 68400 | E53: Pittsburgh | F53: Pennsylvania | G53: 2001 | H53: Football | I53: Pittsburgh Steelers (NFL) Pittsburgh Panthers (NCAA)
B54: 44 | C54: EverBank Stadium | D54: 67814 | E54: Jacksonville | F54: Florida | G54: 1995 | H54: Football | I54: Jacksonville Jaguars (NFL) Gator Bowl (NCAA) Florida vs. Georgia Football Classic (NCAA)
B55: 45 | C55: Lincoln Financial Field | D55: 67594 | E55: Philadelphia | F55: Pennsylvania | G55: 2003 | H55: Football | I55: Philadelphia Eagles (NFL) Temple Owls (NCAA) Army–Navy Game (NCAA) (most years)
... B71: 61 | C71: Faurot Field | D71: 61620 | E71: Columbia | F71: Missouri | G71: 1926 | H71: Football | I71: Missouri Tigers (NCAA)
B72: 62 | C72: Soldier Field | D72: 61500 | E72: Chicago | F72: Illinois | G72: 1924;2003 | H72: Football, soccer | I72: Chicago Bears (NFL) Chicago Fire (MLS)
B73: 63 | C73: Scott Stadium | D73: 61500 | E73: Charlottesville | F73: Virginia | G73: 1931 | H73: Football | I73: Virginia Cavaliers (NCAA)
B74: 64 | C74: Jack Trice Stadium | D74: 61500 | E74: Ames | F74: Iowa | G74: 1975 | H74: Football | I74: Iowa State Cyclones (NCAA)
B75: 65 | C75: Yale Bowl | D75: 61446 | E75: New Haven | F75: Connecticut | G75: 1914 | H75: Football | I75: Yale Bulldogs (NCAA)
B76: 66 | C76: Ross–Ade Stadium | D76: 61441 | E76: West Lafayette | F76: Indiana | G76: 1924 | H76: Football | I76: Purdue Boilermakers (NCAA)
...

Sheet Arenas
A1: Stadiums in the United States
A2: Arenas
B4: List of largest municipal and privately owned arenas in the United States by seating capacity
B6: This is a list of seating capacities for sports and entertainment arenas in the United States with at least 1,000 seats. The list is composed mostly of arenas that house sports teams (basketball, ice hockey, arena soccer and arena football)
B7: and serve as indoor venues for concerts and expositions. The arenas in this table are ranked by maximum capacity. Domed stadiums (such as the Superdome in New Orleans and the U.S. Bank Stadium in Minneapolis) are excluded from this list.
B8: https://en.wikipedia.org/wiki/List_of_indoor_arenas_in_the_United_States
B9: Rows shaded in yellow indicates arena is permanent home to an NBA, NHL, or WNBA franchise.
B11: # | C11: Image | D11: Arena/venue | E11: City | F11: State | G11: Max. | H11: Basket. | I11: Hockey | J11: Average Capacity | K11: Major tenant(s) | L11: Open | M11: Area
B12: 1 | D12: Greensboro Coliseum | E12: Greensboro | F12: North Carolina | G12: 23500 | H12: 22000 | I12: 18947 | J12: =AVERAGE(G12:I12) -> 21482.333 | K12: UNC Greensboro Spartans (NCAA) | L12: 1959
B13: 2 | D13: United Center | E13: Chicago | F13: Illinois | G13: 23500 | H13: 20917 | I13: 19717 | J13: =AVERAGE(G13:I13) -> 21378 | K13: Chicago Blackhawks (NHL) Chicago Bulls (NBA) | L13: 1994 | M13: Chicagoland
B14: 3 | D14: KFC Yum! Center | E14: Louisville | F14: Kentucky | G14: 23084 | H14: 22090 | I14: 21000 | J14: =AVERAGE(G14:I14) -> 22058 | K14: Louisville Cardinals (NCAA) | L14: 2010
B15: 4 | D15: Tacoma Dome | E15: Tacoma | F15: Washington | G15: 23000 | H15: 20722 | I15: 19106 | J15: =AVERAGE(G15:I15) -> 20942.667 | L15: 1983 | M15: Seattle-Tacoma area
B16: 5 | D16: Amerant Bank Arena | E16: Sunrise | F16: Florida | G16: 22457 | H16: 20737 | I16: 19250 | J16: =AVERAGE(G16:I16) -> 20814.667 | K16: Florida Panthers (NHL) | L16: 1998 | M16: Miami metropolitan area
B17: 6 | D17: Enterprise Center | E17: St. Louis | F17: Missouri | G17: 22000 | H17: 21000 | I17: 19150 | J17: =AVERAGE(G17:I17) -> 20716.667 | K17: St. Louis Blues (NHL) | L17: 1994 | M17: Greater St. Louis
B18: 7 | D18: Amalie Arena | E18: Tampa | F18: Florida | G18: 21817 | H18: 20500 | I18: 19092 | J18: =AVERAGE(G18:I18) -> 20469.667 | K18: Tampa Bay Lightning (NHL) | L18: 1996 | M18: Tampa Bay
B19: 8 | D19: Wells Fargo Center | E19: Philadelphia | F19: Pennsylvania | G19: 21600 | H19: 20318 | I19: 19543 | J19: =AVERAGE(G19:I19) -> 20487 | K19: Philadelphia 76ers (NBA) Philadelphia Flyers (NHL) Philadelphia Wings (NLL) | L19: 1996 | M19: Greater Philadelphia
B20: 9 | D20: Lenovo Center | E20: Raleigh | F20: North Carolina | G20: 21500 | H20: 19500 | I20: 18700 | J20: =AVERAGE(G20:I20) -> 19900 | K20: Carolina Hurricanes (NHL) NC State Wolfpack (NCAA) | L20: 1999
B21: 10 | D21: Rupp Arena | E21: Lexington | F21: Kentucky | G21: 21500 | H21: 20545 | I21: 18345 | J21: =AVERAGE(G21:I21) -> 20130 | K21: Kentucky Wildcats (NCAA) | L21: 1976
B22: 11 | D22: Delta Center | E22: Salt Lake City | F22: Utah | G22: 21000 | H22: 19911 | I22: 14000 | J22: =AVERAGE(G22:I22) -> 18303.667 | K22: Utah Jazz (NBA) | L22: 1991
B23: 12 | D23: Little Caesars Arena | E23: Detroit | F23: Michigan | G23: 21000 | H23: 20491 | I23: 19515 | J23: =AVERAGE(G23:I23) -> 20335.333 | K23: Detroit Red Wings (NHL) Detroit Pistons (NBA) | L23: 2017
B24: 13 | D24: Moda Center | E24: Portland | F24: Oregon | G24: 21000 | H24: 19980 | I24: 18280 | J24: =AVERAGE(G24:I24) -> 19753.333 | K24: Portland Trail Blazers (NBA) Portland Winterhawks (WHL) | L24: 1995
B25: 14 | D25: Ball Arena | E25: Denver | F25: Colorado | G25: 21000 | H25: 19155 | I25: 18007 | J25: =AVERAGE(G25:I25) -> 19387.333 | K25: Colorado Avalanche (NHL) Denver Nuggets (NBA) Colorado Mammoth (NLL) | L25: 1999 | M25: Denver metropolitan area
B26: 15 | D26: State Farm Arena | E26: Atlanta | F26: Georgia | G26: 21000 | H26: 18047 | I26: 17624 | J26: =AVERAGE(G26:I26) -> 18890.333 | K26: Atlanta Hawks (NBA) | L26: 1999 | M26: Metro Atlanta
B27: 16 | D27: Capital One Arena | E27: Washington | F27: District of Columbia | G27: 21000 | H27: 20308 | I27: 18506 | J27: =AVERAGE(G27:I27) -> 19938 | K27: Washington Capitals (NHL) Washington Wizards (NBA) Georgetown Hoyas (NCAA) | L27: 1997 | M27: Washington–Baltimore metropolitan area
B28: 17 | D28: Madison Square Garden | E28: New York City | F28: New York | G28: 20789 | H28: 19812 | I28: 18006 | J28: =AVERAGE(G28:I28) -> 19535.667 | K28: New York Knicks (NBA) New York Rangers (NHL) St. John's Red Storm (NCAA) | L28: 1968 | M28: New York metropolitan area
B29: 18 | D29: Target Center | E29: Minneapolis | F29: Minnesota | G29: 20500 | H29: 19356 | I29: 17500 | J29: =AVERAGE(G29:I29) -> 19118.667 | K29: Minnesota Timberwolves (NBA) Minnesota Lynx (WNBA) | L29: 1990 | M29: Twin Cities
B30: 19 | D30: Spectrum Center | E30: Charlotte | F30: North Carolina | G30: 20200 | H30: 19077 | I30: 14100 | J30: =AVERAGE(G30:I30) -> 17792.333 | K30: Charlotte Hornets (NBA) | L30: 2005
B31: 20 | D31: Kaseya Center | E31: Miami | F31: Florida | G31: 20000 | H31: 19600 | I31: 14447 | J31: =AVERAGE(G31:I31) -> 18015.667 | K31: Miami Heat (NBA) | L31: 1999 | M31: Miami metropolitan area
B32: 21 | D32: American Airlines Center | E32: Dallas | F32: Texas | G32: 20000 | H32: 19200 | I32: 18532 | J32: =AVERAGE(G32:I32) -> 19244 | K32: Dallas Mavericks (NBA) Dallas Stars (NHL) | L32: 2001 | M32: Dallas–Fort Worth metroplex
B33: 22 | D33: Kia Center | E33: Orlando | F33: Florida | G33: 20000 | H33: 18846 | I33: 17353 | J33: =AVERAGE(G33:I33) -> 18733 | K33: Orlando Magic (NBA) Orlando Solar Bears (ECHL) | L33: 2010
B34: 23 | D34: Gainbridge Fieldhouse | E34: Indianapolis | F34: Indiana | G34: 20000 | H34: 18165 | I34: 15490 | J34: =AVERAGE(G34:I34) -> 17885 | K34: Indiana Pacers (NBA) Indiana Fever (WNBA) | L34: 1999
B35: 24 | D35: Bridgestone Arena | E35: Nashville | F35: Tennessee | G35: 20000 | H35: 19395 | I35: 17113 | J35: =AVERAGE(G35:I35) -> 18836 | K35: Nashville Predators (NHL) | L35: 1996
B36: 25 | D36: Nationwide Arena | E36: Columbus | F36: Ohio | G36: 20000 | H36: 19500 | I36: 18144 | J36: =AVERAGE(G36:I36) -> 19214.667 | K36: Columbus Blue Jackets (NHL) | L36: 2000
B37: 26 | D37: Oakland Arena | E37: Oakland | F37: California | G37: 20000 | H37: 19596 | I37: 17268 | J37: =AVERAGE(G37:I37) -> 18954.667 | L37: 1966 | M37: Bay Area
B38: 27 | D38: SAP Center at San Jose | E38: San Jose | F38: California | G38: 20000 | H38: 18543 | I38: 17562 | J38: =AVERAGE(G38:I38) -> 18701.667 | K38: San Jose Sharks (NHL) | L38: 1993 | M38: Bay Area
B39: 28 | D39: Crypto.com Arena | E39: Los Angeles | F39: California | G39: 20000 | H39: 18997 | I39: 18230 | J39: =AVERAGE(G39:I39) -> 19075.667 | K39: Los Angeles Kings (NHL) Los Angeles Lakers (NBA) Los Angeles Sparks (WNBA) | L39: 1999 | M39: Greater Los Angeles
B40: 29 | D40: T-Mobile Arena | E40: Paradise | F40: Nevada | G40: 20000 | H40: 18800 | I40: 17500 | J40: =AVERAGE(G40:I40) -> 18766.667 | K40: Vegas Golden Knights (NHL) | L40: 2016
B41: 30 | D41: Paycom Center | E41: Oklahoma City | F41: Oklahoma | G41: 19711 | H41: 18203 | I41: 18036 | J41: =AVERAGE(G41:I41) -> 18650 | K41: Oklahoma City Thunder (NBA) Oklahoma City Blue (NBA G League) | L41: 2002
B42: 31 | D42: TD Garden | E42: Boston | F42: Massachusetts | G42: 19580 | H42: 18624 | I42: 17565 | J42: =AVERAGE(G42:I42) -> 18589.667 | K42: Boston Bruins (NHL) Boston Celtics (NBA) | L42: 1995 | M42: Greater Boston
B43: 32 | D43: PPG Paints Arena | E43: Pittsburgh | F43: Pennsylvania | G43: 19578 | H43: 19100 | I43: 18387 | J43: =AVERAGE(G43:I43) -> 19021.667 | K43: Pittsburgh Penguins (NHL) | L43: 2010
...

Sheet College Arenas > 10,000
A1: College/University Arenas
A2: Capacity > 10,000
B4: This table includes indoor arenas by seating capacity, which are owned and operated by universities and colleges and serve as home to college sports teams. Arenas with a capacity of at
B5: least 10,000 are included. Arenas which are shared by both professional and college teams, appear on the table of municipal arenas above. Domed stadiums are excluded from this list,
B6: with the exception of those which can be configured to serve as the home of major college basketball programs (i.e. the JMA Wireless Dome).
B7: https://en.wikipedia.org/wiki/List_of_indoor_arenas_in_the_United_States
B9: # | C9: Arena/venue | D9: City | E9: State | F9: Max. | G9: Basket. | H9: Hockey | I9: Average | J9: Major tenant(s) | K9: Open
B10: 1 | C10: JMA Wireless Dome | D10: Syracuse | E10: New York | F10: 49207 | G10: 35642 | I10: =AVERAGE(F10:H10) -> 42424.5 | J10: Syracuse Orange | K10: 1980
B11: 2 | C11: Dean Smith Center | D11: Chapel Hill | E11: North Carolina | F11: 21750 | G11: 21750 | I11: =AVERAGE(F11:H11) -> 21750 | J11: North Carolina Tar Heels | K11: 1986
B12: 3 | C12: Thompson–Boling Arena | D12: Knoxville | E12: Tennessee | F12: 21678 | G12: 21678 | I12: =AVERAGE(F12:H12) -> 21678 | J12: Tennessee Volunteers | K12: 1987
B13: 4 | C13: Thomas & Mack Center | D13: Paradise | E13: Nevada | F13: 19522 | G13: 18500 | H13: 16606 | I13: =AVERAGE(F13:H13) -> 18209.333 | J13: UNLV Runnin' Rebels | K13: 1983
B14: 5 | C14: Bud Walton Arena | D14: Fayetteville | E14: Arkansas | F14: 19368 | G14: 19368 | I14: =AVERAGE(F14:H14) -> 19368 | J14: Arkansas Razorbacks | K14: 1993
B15: 6 | C15: Colonial Life Arena | D15: Columbia | E15: South Carolina | F15: 19000 | G15: 18000 | I15: =AVERAGE(F15:H15) -> 18500 | J15: South Carolina Gamecocks | K15: 2002
B16: 7 | C16: Marriott Center | D16: Provo | E16: Utah | F16: 18987 | G16: 18987 | I16: =AVERAGE(F16:H16) -> 18987 | J16: BYU Cougars | K16: 1971
B17: 8 | C17: Value City Arena | D17: Columbus | E17: Ohio | F17: 18809 | G17: 18809 | H17: 17500 | I17: =AVERAGE(F17:H17) -> 18372.667 | J17: Ohio State Buckeyes | K17: 1998
B18: 9 | C18: Xfinity Center | D18: College Park | E18: Maryland | F18: 17950 | G18: 17950 | I18: =AVERAGE(F18:H18) -> 17950 | J18: Maryland Terrapins | K18: 2002
B19: 10 | C19: Kohl Center | D19: Madison | E19: Wisconsin | F19: 17230 | G19: 17230 | H19: 15359 | I19: =AVERAGE(F19:H19) -> 16606.333 | J19: Wisconsin Badgers | K19: 1998
B20: 11 | C20: Simon Skjodt Assembly Hall | D20: Bloomington | E20: Indiana | F20: 17222 | G20: 17222 | I20: =AVERAGE(F20:H20) -> 17222 | J20: Indiana Hoosiers | K20: 1971
B21: 12 | C21: Allen Fieldhouse | D21: Lawrence | E21: Kansas | F21: 16300 | G21: 16300 | I21: =AVERAGE(F21:H21) -> 16300 | J21: Kansas Jayhawks | K21: 1955
B22: 13 | C22: Save Mart Center | D22: Fresno | E22: California | F22: 16182 | G22: 15544 | H22: 14224 | I22: =AVERAGE(F22:H22) -> 15316.667 | J22: Fresno State Bulldogs | K22: 2003
B23: 14 | C23: State Farm Center | D23: Champaign | E23: Illinois | F23: 15500 | G23: 15500 | I23: =AVERAGE(F23:H23) -> 15500 | J23: Illinois Fighting Illini | K23: 1963
B24: 15 | C24: Dreamstyle Arena | D24: Albuquerque | E24: New Mexico | F24: 15411 | G24: 15411 | I24: =AVERAGE(F24:H24) -> 15411 | J24: New Mexico Lobos | K24: 1966
B25: 16 | C25: Carver–Hawkeye Arena | D25: Iowa City | E25: Iowa | F25: 15400 | G25: 15500 | I25: =AVERAGE(F25:H25) -> 15450 | J25: Iowa Hawkeyes | K25: 1983
B26: 17 | C26: Coleman Coliseum | D26: Tuscaloosa | E26: Alabama | F26: 15383 | G26: 15383 | I26: =AVERAGE(F26:H26) -> 15383 | J26: Alabama Crimson Tide | K26: 1968
B27: 18 | C27: Bryce Jordan Center | D27: University Park | E27: Pennsylvania | F27: 15261 | G27: 15261 | I27: =AVERAGE(F27:H27) -> 15261 | J27: Penn State Nittany Lions | K27: 1996
B28: 19 | C28: United Supermarkets Arena | D28: Lubbock | E28: Texas | F28: 15098 | G28: 15098 | I28: =AVERAGE(F28:H28) -> 15098 | J28: Texas Tech Red Raiders | K28: 1999
B29: 20 | C29: Mizzou Arena | D29: Columbia | E29: Missouri | F29: 15061 | G29: 15061 | I29: =AVERAGE(F29:H29) -> 15061 | J29: Missouri Tigers | K29: 2004
B30: 21 | C30: Arena-Auditorium | D30: Laramie | E30: Wyoming | F30: 15028 | G30: 15028 | I30: =AVERAGE(F30:H30) -> 15028 | J30: Wyoming Cowboys and Cowgirls | K30: 1982
B31: 22 | C31: Jon M. Huntsman Center | D31: Salt Lake City | E31: Utah | F31: 15000 | G31: 15000 | I31: =AVERAGE(F31:H31) -> 15000 | J31: Utah Utes | K31: 1969
B32: 23 | C32: Moody Center | D32: Austin | E32: Texas | F32: 15000 | G32: 10763 | I32: =AVERAGE(F32:H32) -> 12881.5 | J32: Texas Longhorns | K32: 2022
B33: 24 | C33: Mackey Arena | D33: West Lafayette | E33: Indiana | F33: 14804 | G33: 14804 | I33: =AVERAGE(F33:H33) -> 14804 | J33: Purdue Boilermakers | K33: 1967
B34: 25 | C34: Breslin Student Events Center | D34: East Lansing | E34: Michigan | F34: 14759 | G34: 14759 | I34: =AVERAGE(F34:H34) -> 14759 | J34: Michigan State Spartans | K34: 1989
B35: 26 | C35: Lawrence Joel Veterans Memorial Coliseum | D35: Winston-Salem | E35: North Carolina | F35: 14665 | G35: 14665 | H35: 14571 | I35: =AVERAGE(F35:H35) -> 14633.667 | J35: Wake Forest Demon Deacons | K35: 1989
B36: 27 | C36: McKale Center | D36: Tucson | E36: Arizona | F36: 14644 | G36: 14644 | I36: =AVERAGE(F36:H36) -> 14644 | J36: Arizona Wildcats | K36: 1973
B37: 28 | C37: Williams Arena | D37: Minneapolis | E37: Minnesota | F37: 14625 | G37: 14625 | I37: =AVERAGE(F37:H37) -> 14625 | J37: Minnesota Golden Gophers | K37: 1928
B38: 29 | C38: John Paul Jones Arena | D38: Charlottesville | E38: Virginia | F38: 14593 | G38: 14593 | I38: =AVERAGE(F38:H38) -> 14593 | J38: Virginia Cavaliers | K38: 2006
B39: 30 | C39: Hilton Coliseum | D39: Ames | E39: Iowa | F39: 14384 | G39: 14384 | I39: =AVERAGE(F39:H39) -> 14384 | J39: Iowa State Cyclones | K39: 1971
B40: 31 | C40: Memorial Gymnasium | D40: Nashville | E40: Tennessee | F40: 14316 | G40: 14316 | I40: =AVERAGE(F40:H40) -> 14316 | J40: Vanderbilt Commodores | K40: 1952
B41: 32 | C41: WVU Coliseum | D41: Morgantown | E41: West Virginia | F41: 14000 | G41: 14000 | I41: =AVERAGE(F41:H41) -> 14000 | J41: West Virginia Mountaineers | K41: 1970
B42: 33 | C42: Pauley Pavilion | D42: Los Angeles | E42: California | F42: 13800 | G42: 13800 | I42: =AVERAGE(F42:H42) -> 13800 | J42: UCLA Bruins | K42: 1965
...

Sheet College Arenas 5,000-10,000
A1: College/University Arenas
A2: Capacity 5,000 - 10,000
B4: This table includes indoor arenas by seating capacity, which are owned and operated by universities and colleges and serve as home to college
B5: sports teams. Arenas with a capacity of at least 5,000 are included.
B6: https://en.wikipedia.org/wiki/List_of_indoor_arenas_in_the_United_States
C8: Image | D8: Arena | E8: City | F8: State | G8: Team | H8: Conference | I8: Capacity | J8: Opened
B9: 1 | D9: Al Lawson Center | E9: Tallahassee | F9: Florida | G9: Florida A&M | H9: SWAC | I9: 9639 | J9: 2009
B10: =B9+1 -> 2 | D10: Gill Coliseum | E10: Corvallis | F10: Oregon | G10: Oregon State | H10: Pac-12 | I10: 9604 | J10: 1949
B11: =B10+1 -> 3 | D11: The Sandy and John Black Pavilion at Ole Miss | E11: Oxford | F11: Mississippi | G11: Ole Miss | H11: SEC | I11: 9500 | J11: 2016
B12: =B11+1 -> 4 | D12: Mullins Center | E12: Amherst | F12: Massachusetts | G12: Massachusetts | H12: Atlantic 10 | I12: 9493 | J12: 1993
B13: =B12+1 -> 5 | D13: Addition Financial Arena | E13: Orlando | F13: Florida | G13: UCF | H13: The American (Big 12 in 2023) | I13: 9465 | J13: 2007
B14: =B13+1 -> 6 | D14: Truist Arena | E14: Highland Heights | F14: Kentucky | G14: Northern Kentucky | H14: Horizon | I14: 9400 | J14: 2008
B15: =B14+1 -> 7 | D15: Cameron Indoor Stadium | E15: Durham | F15: North Carolina | G15: Duke | H15: ACC | I15: 9314 | J15: 1940
B16: =B15+1 -> 8 | D16: Eblen Center | E16: Cookeville | F16: Tennessee | G16: Tennessee Tech | H16: Ohio Valley | I16: 9282 | J16: 1977
B17: =B16+1 -> 9 | D17: Edmund P. Joyce Center | E17: Notre Dame | F17: Indiana | G17: Notre Dame | H17: ACC | I17: 9149 | J17: 1968
B18: =B17+1 -> 10 | D18: Dale F. Halton Arena | E18: Charlotte | F18: North Carolina | G18: Charlotte | H18: C-USA (The American in 2023) | I18: 9105 | J18: 1996
B19: =B18+1 -> 11 | D19: Hinkle Fieldhouse | E19: Indianapolis | F19: Indiana | G19: Butler | H19: Big East | I19: 9100 | J19: 1928
B20: =B19+1 -> 12 | D20: Cam Henderson Center | E20: Huntington | F20: West Virginia | G20: Marshall | H20: C-USA (Sun Belt in 2023) | I20: 9048 | J20: 1981
B21: =B20+1 -> 13 | D21: Dunn Center | E21: Clarksville | F21: Tennessee | G21: Austin Peay | H21: ASUN | I21: 9000 | J21: 1975
... B87: =B86+1 -> 79 | D87: Alumni Coliseum | E87: Richmond | F87: Kentucky | G87: Eastern Kentucky | H87: ASUN | I87: 6500 | J87: 1963
B88: =B87+1 -> 80 | D88: William J. Nicks Building | E88: Prairie View | F88: Texas | G88: Prairie View A&M | H88: SWAC | I88: 6500 | J88: 1968[3]
B89: =B88+1 -> 81 | D89: Jerry M. Hughes Athletics Center | E89: Warrensburg | F89: Missouri | G89: Central Missouri | H89: MIAA | I89: 6500 | J89: 1976
B90: =B89+1 -> 82 | D90: Frost Arena | E90: Brookings | F90: South Dakota | G90: South Dakota State | H90: Summit | I90: 6500 | J90: 1973
B91: =B90+1 -> 83 | D91: Beeghly Center | E91: Youngstown | F91: Ohio | G91: Youngstown State | H91: Horizon | I91: 6500 | J91: 1972
B92: =B91+1 -> 84 | D92: Ellis Johnson Arena | E92: Morehead | F92: Kentucky | G92: Morehead State | H92: Ohio Valley | I92: 6500 | J92: 1981
B93: =B92+1 -> 85 | D93: Tsongas Center | E93: Lowell | F93: Massachusetts | G93: UMass Lowell | H93: America East | I93: 6496 | J93: 1998
B94: =B93+1 -> 86 | D94: Munn Ice Arena | E94: East Lansing | F94: Michigan | G94: Michigan State | H94: Big Ten | I94: 6470 | J94: 1974
B95: =B94+1 -> 87 | D95: The Coliseum | E95: Carrollton | F95: Georgia | G95: West Georgia Wolves | H95: GSC | I95: 6469 | J95: 2009[5]
B96: =B95+1 -> 88 | D96: Knapp Center | E96: Des Moines | F96: Iowa | G96: Drake | H96: Missouri Valley | I96: 6424 | J96: 1992
B97: =B96+1 -> 89 | D97: Halenbeck Hall | E97: St. Cloud | F97: Minnesota | G97: St. Cloud State Huskies | H97: Northern Sun | I97: 6400 | J97: 1965
B98: =B97+1 -> 90 | D98: Millett Hall | E98: Oxford | F98: Ohio | G98: Miami (Ohio) | H98: MAC | I98: 6400 | J98: 1968
B99: =B98+1 -> 91 | D99: Memorial Athletic and Convocation Center | E99: Kent | F99: Ohio | G99: Kent State | H99: MAC | I99: 6327 | J99: 1950
B100: =B99+1 -> 92 | D100: Alex G. Spanos Center | E100: Stockton | F100: California | G100: Pacific | H100: West Coast | I100: 6150 | J100: 1981
B101: =B100+1 -> 93 | D101: Agganis Arena | E101: Boston | F101: Massachusetts | G101: Boston University men | H101: Hockey East | I101: 6150 | J101: 2005
B102: =B101+1 -> 94 | D102: Freedom Hall Civic Center | E102: Johnson City | F102: Tennessee | G102: East Tennessee State | H102: Southern | I102: 6149 | J102: 1974
B103: =B102+1 -> 95 | D103: Winthrop Coliseum | E103: Rock Hill | F103: South Carolina | G103: Winthrop | H103: Big South | I103: 6100 | J103: 1982
B104: =B103+1 -> 96 | D104: Alumni Arena | E104: Amherst | F104: New York | G104: Buffalo | H104: MAC | I104: 6100 | J104: 1982
B105: =B104+1 -> 97 | D105: Bernard Johnson Coliseum | E105: Huntsville | F105: Texas | G105: Sam Houston | H105: WAC (C-USA in 2023) | I105: 6100 | J105: 1976
B106: =B105+1 -> 98 | D106: Pegula Ice Arena | E106: University Park | F106: Pennsylvania | G106: Penn State men & women | H106: Big Ten (men) CHA (women) | I106: 6000 | J106: 2013
B107: =B106+1 -> 99 | D107: Stabler Arena | E107: Bethlehem | F107: Pennsylvania | G107: Lehigh | H107: Patriot | I107: 6000 | J107: 1979
...
